Workbook

Sheet System Generated 2026-08-24
A1: Item | B1: Current Stock | C1: Unit | D1: Average Purchase Price (Rs) | E1: Total (Rs) | F1: Last Stock Update
A2: 3cp | B2: 675 | C2: pcs | D2: 8.18 | E2: 5522.48 | F2: 2026-08-06
A3: 5cp | B3: 248 | C3: pcs | D3: 12 | E3: 2976 | F3: 2026-08-06
A4: 8cp | B4: 274 | C4: pcs | D4: 16.58 | E4: 4543.41 | F4: 2026-08-06
A5: Almond Syrup | B5: 3 | C5: bottle | D5: 370 | E5: 1110 | F5: 2026-08-12
A6: Amchoor Powder | B6: 0 | C6: kg | D6: 556 | E6: 0 | F6: 2026-08-06
A7: Amchur Raw | B7: 2 | C7: kg | D7: 544 | E7: 1088 | F7: 2026-08-06
A8: Anar | B8: 0 | C8: kg | D8: 220 | E8: 0 | F8: 2026-08-10
A9: Anti Flies Floor Cleaner | B9: 5 | C9: L | D9: 165 | E9: 825 | F9: 2026-08-12
A10: Apples | B10: 0 | C10: kg | D10: 236.81 | E10: 0 | F10: 2026-08-10
A11: Aratikayalu | B11: 0 | C11: kg | D11: 50 | E11: 0 | F11: 2026-08-06
A12: Aromatic Powder | B12: 4.1 | C12: kg | D12: 356.45 | E12: 1461.43 | F12: 2026-08-12
A13: Atta | B13: 186.5 | C13: kg | D13: 38.65 | E13: 7208.15 | F13: 2026-08-12
... A394: Wooden Spoons Small | B394: 36 | C394: pkt | D394: 40 | E394: 1440 | F394: 2026-08-06

Sheet Kapila hotel 21-08-26
A1: Item | B1: Current Stock | C1: Average Purchase Price (₹) | D1: Total (₹)
A2: 5cp | B2: 248 | C2: 12 | D2: 2976
A3: 20-20 | B3: 0 | C3: 707.143 | D3: 0
A4: 3cp | B4: 675 | C4: 8.18145 | D4: 5522.479
A5: 8cp | B5: 274 | C5: 16.5818 | D5: 4543.413
A6: Almond Syrup | B6: 3 | C6: 370 | D6: 1110
A7: Amchoor Powder | B7: 0 | C7: 556 | D7: 0
A8: Amchur Raw | B8: 2 | C8: 544 | D8: 1088
A9: Anar | B9: 0 | C9: 220 | D9: 0
A10: Anti Flies Floor Cleaner | B10: 5 | C10: 165 | D10: 825
A11: Apples | B11: 0 | C11: 236.806 | D11: 0
A12: Aratikayalu | B12: 0 | C12: 50 | D12: 0
A13: Aromatic Powder | B13: 4.1 | C13: 356.447 | D13: 1461.433
... A447: Wooden Spoons Small | B447: 36 | C447: 40 | D447: 1440

Sheet Discrepancy Report
A1: Item | B1: App Stock | C1: Hotel Stock | D1: Stock Diff (App-Hotel) | E1: App Total (₹) | F1: Hotel Total (₹) | G1: Value Diff (₹) | H1: Status | K1: Helper: combined item list (do not edit) | M1: Summary
A2: {=_xlfn._xlws.SORT(_xlfn.UNIQUE(K2:K840))} -> 20-20 | B2: =IF($A2="","",IFERROR(_xlfn.XLOOKUP($A2,'System Generated 2026-08-24'!$A:$A,'System Generated 2026-08-24'!$B:$B),"Missing")) -> Missing | C2: =IF($A2="","",IFERROR(_xlfn.XLOOKUP($A2,Table1[Item],Table1[Current Stock]),"Missing")) -> 0 | D2: =IF($A2="","",IF(OR(B2="Missing",C2="Missing"),"N/A",B2-C2)) -> N/A | E2: =IF($A2="","",IFERROR(_xlfn.XLOOKUP($A2,'System Generated 2026-08-24'!$A:$A,'System Generated 2026-08-24'!$E:$E),"Missing")) -> Missing | F2: =IF($A2="","",IFERROR(_xlfn.XLOOKUP($A2,Table1[Item],Table1[Total (₹)]),"Missing")) -> 0 | G2: =IF($A2="","",IF(OR(E2="Missing",F2="Missing"),"N/A",E2-F2)) -> N/A | H2: =IF($A2="","",IF(B2="Missing","Missing in App",IF(C2="Missing","Missing in Hotel Data",IF(D2=0,"Match","Discrepancy")))) -> Missing in App | K2: ='System Generated 2026-08-24'!A2 -> 3cp | M2: Total unique items | N2: =COUNTIF(A2:A480,"?*") -> 473
A3: 3cp | B3: =IF($A3="","",IFERROR(_xlfn.XLOOKUP($A3,'System Generated 2026-08-24'!$A:$A,'System Generated 2026-08-24'!$B:$B),"Missing")) -> 675 | C3: =IF($A3="","",IFERROR(_xlfn.XLOOKUP($A3,Table1[Item],Table1[Current Stock]),"Missing")) -> 675 | D3: =IF($A3="","",IF(OR(B3="Missing",C3="Missing"),"N/A",B3-C3)) -> 0 | E3: =IF($A3="","",IFERROR(_xlfn.XLOOKUP($A3,'System Generated 2026-08-24'!$A:$A,'System Generated 2026-08-24'!$E:$E),"Missing")) -> 5522.48 | F3: =IF($A3="","",IFERROR(_xlfn.XLOOKUP($A3,Table1[Item],Table1[Total (₹)]),"Missing")) -> 5522.479 | G3: =IF($A3="","",IF(OR(E3="Missing",F3="Missing"),"N/A",E3-F3)) -> 0.001 | H3: =IF($A3="","",IF(B3="Missing","Missing in App",IF(C3="Missing","Missing in Hotel Data",IF(D3=0,"Match","Discrepancy")))) -> Match | K3: ='System Generated 2026-08-24'!A3 -> 5cp | M3: Matches | N3: =COUNTIF(H2:H480,"Match") -> 365
A4: 5cp | B4: =IF($A4="","",IFERROR(_xlfn.XLOOKUP($A4,'System Generated 2026-08-24'!$A:$A,'System Generated 2026-08-24'!$B:$B),"Missing")) -> 248 | C4: =IF($A4="","",IFERROR(_xlfn.XLOOKUP($A4,Table1[Item],Table1[Current Stock]),"Missing")) -> 248 | D4: =IF($A4="","",IF(OR(B4="Missing",C4="Missing"),"N/A",B4-C4)) -> 0 | E4: =IF($A4="","",IFERROR(_xlfn.XLOOKUP($A4,'System Generated 2026-08-24'!$A:$A,'System Generated 2026-08-24'!$E:$E),"Missing")) -> 2976 | F4: =IF($A4="","",IFERROR(_xlfn.XLOOKUP($A4,Table1[Item],Table1[Total (₹)]),"Missing")) -> 2976 | G4: =IF($A4="","",IF(OR(E4="Missing",F4="Missing"),"N/A",E4-F4)) -> 0 | H4: =IF($A4="","",IF(B4="Missing","Missing in App",IF(C4="Missing","Missing in Hotel Data",IF(D4=0,"Match","Discrepancy")))) -> Match | K4: ='System Generated 2026-08-24'!A4 -> 8cp | M4: Stock discrepancies | N4: =COUNTIF(H2:H480,"Discrepancy") -> 1
A5: 8cp | B5: =IF($A5="","",IFERROR(_xlfn.XLOOKUP($A5,'System Generated 2026-08-24'!$A:$A,'System Generated 2026-08-24'!$B:$B),"Missing")) -> 274 | C5: =IF($A5="","",IFERROR(_xlfn.XLOOKUP($A5,Table1[Item],Table1[Current Stock]),"Missing")) -> 274 | D5: =IF($A5="","",IF(OR(B5="Missing",C5="Missing"),"N/A",B5-C5)) -> 0 | E5: =IF($A5="","",IFERROR(_xlfn.XLOOKUP($A5,'System Generated 2026-08-24'!$A:$A,'System Generated 2026-08-24'!$E:$E),"Missing")) -> 4543.41 | F5: =IF($A5="","",IFERROR(_xlfn.XLOOKUP($A5,Table1[Item],Table1[Total (₹)]),"Missing")) -> 4543.413 | G5: =IF($A5="","",IF(OR(E5="Missing",F5="Missing"),"N/A",E5-F5)) -> -0.003 | H5: =IF($A5="","",IF(B5="Missing","Missing in App",IF(C5="Missing","Missing in Hotel Data",IF(D5=0,"Match","Discrepancy")))) -> Match | K5: ='System Generated 2026-08-24'!A5 -> Almond Syrup | M5: Missing in App | N5: =COUNTIF(H2:H480,"Missing in App") -> 80
A6: Almond Syrup | B6: =IF($A6="","",IFERROR(_xlfn.XLOOKUP($A6,'System Generated 2026-08-24'!$A:$A,'System Generated 2026-08-24'!$B:$B),"Missing")) -> 3 | C6: =IF($A6="","",IFERROR(_xlfn.XLOOKUP($A6,Table1[Item],Table1[Current Stock]),"Missing")) -> 3 | D6: =IF($A6="","",IF(OR(B6="Missing",C6="Missing"),"N/A",B6-C6)) -> 0 | E6: =IF($A6="","",IFERROR(_xlfn.XLOOKUP($A6,'System Generated 2026-08-24'!$A:$A,'System Generated 2026-08-24'!$E:$E),"Missing")) -> 1110 | F6: =IF($A6="","",IFERROR(_xlfn.XLOOKUP($A6,Table1[Item],Table1[Total (₹)]),"Missing")) -> 1110 | G6: =IF($A6="","",IF(OR(E6="Missing",F6="Missing"),"N/A",E6-F6)) -> 0 | H6: =IF($A6="","",IF(B6="Missing","Missing in App",IF(C6="Missing","Missing in Hotel Data",IF(D6=0,"Match","Discrepancy")))) -> Match | K6: ='System Generated 2026-08-24'!A6 -> Amchoor Powder | M6: Missing in Hotel Data | N6: =COUNTIF(H2:H480,"Missing in Hotel Data") -> 27
A7: Amchoor Powder | B7: =IF($A7="","",IFERROR(_xlfn.XLOOKUP($A7,'System Generated 2026-08-24'!$A:$A,'System Generated 2026-08-24'!$B:$B),"Missing")) -> 0 | C7: =IF($A7="","",IFERROR(_xlfn.XLOOKUP($A7,Table1[Item],Table1[Current Stock]),"Missing")) -> 0 | D7: =IF($A7="","",IF(OR(B7="Missing",C7="Missing"),"N/A",B7-C7)) -> 0 | E7: =IF($A7="","",IFERROR(_xlfn.XLOOKUP($A7,'System Generated 2026-08-24'!$A:$A,'System Generated 2026-08-24'!$E:$E),"Missing")) -> 0 | F7: =IF($A7="","",IFERROR(_xlfn.XLOOKUP($A7,Table1[Item],Table1[Total (₹)]),"Missing")) -> 0 | G7: =IF($A7="","",IF(OR(E7="Missing",F7="Missing"),"N/A",E7-F7)) -> 0 | H7: =IF($A7="","",IF(B7="Missing","Missing in App",IF(C7="Missing","Missing in Hotel Data",IF(D7=0,"Match","Discrepancy")))) -> Match | K7: ='System Generated 2026-08-24'!A7 -> Amchur Raw
A8: Amchur Raw | B8: =IF($A8="","",IFERROR(_xlfn.XLOOKUP($A8,'System Generated 2026-08-24'!$A:$A,'System Generated 2026-08-24'!$B:$B),"Missing")) -> 2 | C8: =IF($A8="","",IFERROR(_xlfn.XLOOKUP($A8,Table1[Item],Table1[Current Stock]),"Missing")) -> 2 | D8: =IF($A8="","",IF(OR(B8="Missing",C8="Missing"),"N/A",B8-C8)) -> 0 | E8: =IF($A8="","",IFERROR(_xlfn.XLOOKUP($A8,'System Generated 2026-08-24'!$A:$A,'System Generated 2026-08-24'!$E:$E),"Missing")) -> 1088 | F8: =IF($A8="","",IFERROR(_xlfn.XLOOKUP($A8,Table1[Item],Table1[Total (₹)]),"Missing")) -> 1088 | G8: =IF($A8="","",IF(OR(E8="Missing",F8="Missing"),"N/A",E8-F8)) -> 0 | H8: =IF($A8="","",IF(B8="Missing","Missing in App",IF(C8="Missing","Missing in Hotel Data",IF(D8=0,"Match","Discrepancy")))) -> Match | K8: ='System Generated 2026-08-24'!A8 -> Anar
A9: Anar | B9: =IF($A9="","",IFERROR(_xlfn.XLOOKUP($A9,'System Generated 2026-08-24'!$A:$A,'System Generated 2026-08-24'!$B:$B),"Missing")) -> 0 | C9: =IF($A9="","",IFERROR(_xlfn.XLOOKUP($A9,Table1[Item],Table1[Current Stock]),"Missing")) -> 0 | D9: =IF($A9="","",IF(OR(B9="Missing",C9="Missing"),"N/A",B9-C9)) -> 0 | E9: =IF($A9="","",IFERROR(_xlfn.XLOOKUP($A9,'System Generated 2026-08-24'!$A:$A,'System Generated 2026-08-24'!$E:$E),"Missing")) -> 0 | F9: =IF($A9="","",IFERROR(_xlfn.XLOOKUP($A9,Table1[Item],Table1[Total (₹)]),"Missing")) -> 0 | G9: =IF($A9="","",IF(OR(E9="Missing",F9="Missing"),"N/A",E9-F9)) -> 0 | H9: =IF($A9="","",IF(B9="Missing","Missing in App",IF(C9="Missing","Missing in Hotel Data",IF(D9=0,"Match","Discrepancy")))) -> Match | K9: ='System Generated 2026-08-24'!A9 -> Anti Flies Floor Cleaner
A10: Anti Flies Floor Cleaner | B10: =IF($A10="","",IFERROR(_xlfn.XLOOKUP($A10,'System Generated 2026-08-24'!$A:$A,'System Generated 2026-08-24'!$B:$B),"Missing")) -> 5 | C10: =IF($A10="","",IFERROR(_xlfn.XLOOKUP($A10,Table1[Item],Table1[Current Stock]),"Missing")) -> 5 | D10: =IF($A10="","",IF(OR(B10="Missing",C10="Missing"),"N/A",B10-C10)) -> 0 | E10: =IF($A10="","",IFERROR(_xlfn.XLOOKUP($A10,'System Generated 2026-08-24'!$A:$A,'System Generated 2026-08-24'!$E:$E),"Missing")) -> 825 | F10: =IF($A10="","",IFERROR(_xlfn.XLOOKUP($A10,Table1[Item],Table1[Total (₹)]),"Missing")) -> 825 | G10: =IF($A10="","",IF(OR(E10="Missing",F10="Missing"),"N/A",E10-F10)) -> 0 | H10: =IF($A10="","",IF(B10="Missing","Missing in App",IF(C10="Missing","Missing in Hotel Data",IF(D10=0,"Match","Discrepancy")))) -> Match | K10: ='System Generated 2026-08-24'!A10 -> Apples
A11: Apples | B11: =IF($A11="","",IFERROR(_xlfn.XLOOKUP($A11,'System Generated 2026-08-24'!$A:$A,'System Generated 2026-08-24'!$B:$B),"Missing")) -> 0 | C11: =IF($A11="","",IFERROR(_xlfn.XLOOKUP($A11,Table1[Item],Table1[Current Stock]),"Missing")) -> 0 | D11: =IF($A11="","",IF(OR(B11="Missing",C11="Missing"),"N/A",B11-C11)) -> 0 | E11: =IF($A11="","",IFERROR(_xlfn.XLOOKUP($A11,'System Generated 2026-08-24'!$A:$A,'System Generated 2026-08-24'!$E:$E),"Missing")) -> 0 | F11: =IF($A11="","",IFERROR(_xlfn.XLOOKUP($A11,Table1[Item],Table1[Total (₹)]),"Missing")) -> 0 | G11: =IF($A11="","",IF(OR(E11="Missing",F11="Missing"),"N/A",E11-F11)) -> 0 | H11: =IF($A11="","",IF(B11="Missing","Missing in App",IF(C11="Missing","Missing in Hotel Data",IF(D11=0,"Match","Discrepancy")))) -> Match | K11: ='System Generated 2026-08-24'!A11 -> Aratikayalu
A12: Aratikayalu | B12: =IF($A12="","",IFERROR(_xlfn.XLOOKUP($A12,'System Generated 2026-08-24'!$A:$A,'System Generated 2026-08-24'!$B:$B),"Missing")) -> 0 | C12: =IF($A12="","",IFERROR(_xlfn.XLOOKUP($A12,Table1[Item],Table1[Current Stock]),"Missing")) -> 0 | D12: =IF($A12="","",IF(OR(B12="Missing",C12="Missing"),"N/A",B12-C12)) -> 0 | E12: =IF($A12="","",IFERROR(_xlfn.XLOOKUP($A12,'System Generated 2026-08-24'!$A:$A,'System Generated 2026-08-24'!$E:$E),"Missing")) -> 0 | F12: =IF($A12="","",IFERROR(_xlfn.XLOOKUP($A12,Table1[Item],Table1[Total (₹)]),"Missing")) -> 0 | G12: =IF($A12="","",IF(OR(E12="Missing",F12="Missing"),"N/A",E12-F12)) -> 0 | H12: =IF($A12="","",IF(B12="Missing","Missing in App",IF(C12="Missing","Missing in Hotel Data",IF(D12=0,"Match","Discrepancy")))) -> Match | K12: ='System Generated 2026-08-24'!A12 -> Aromatic Powder
A13: Aromatic Powder | B13: =IF($A13="","",IFERROR(_xlfn.XLOOKUP($A13,'System Generated 2026-08-24'!$A:$A,'System Generated 2026-08-24'!$B:$B),"Missing")) -> 4.1 | C13: =IF($A13="","",IFERROR(_xlfn.XLOOKUP($A13,Table1[Item],Table1[Current Stock]),"Missing")) -> 4.1 | D13: =IF($A13="","",IF(OR(B13="Missing",C13="Missing"),"N/A",B13-C13)) -> 0 | E13: =IF($A13="","",IFERROR(_xlfn.XLOOKUP($A13,'System Generated 2026-08-24'!$A:$A,'System Generated 2026-08-24'!$E:$E),"Missing")) -> 1461.43 | F13: =IF($A13="","",IFERROR(_xlfn.XLOOKUP($A13,Table1[Item],Table1[Total (₹)]),"Missing")) -> 1461.433 | G13: =IF($A13="","",IF(OR(E13="Missing",F13="Missing"),"N/A",E13-F13)) -> -0.003 | H13: =IF($A13="","",IF(B13="Missing","Missing in App",IF(C13="Missing","Missing in Hotel Data",IF(D13=0,"Match","Discrepancy")))) -> Match | K13: ='System Generated 2026-08-24'!A13 -> Atta
A14: Atta | B14: =IF($A14="","",IFERROR(_xlfn.XLOOKUP($A14,'System Generated 2026-08-24'!$A:$A,'System Generated 2026-08-24'!$B:$B),"Missing")) -> 186.5 | C14: =IF($A14="","",IFERROR(_xlfn.XLOOKUP($A14,Table1[Item],Table1[Current Stock]),"Missing")) -> 186.5 | D14: =IF($A14="","",IF(OR(B14="Missing",C14="Missing"),"N/A",B14-C14)) -> 0 | E14: =IF($A14="","",IFERROR(_xlfn.XLOOKUP($A14,'System Generated 2026-08-24'!$A:$A,'System Generated 2026-08-24'!$E:$E),"Missing")) -> 7208.15 | F14: =IF($A14="","",IFERROR(_xlfn.XLOOKUP($A14,Table1[Item],Table1[Total (₹)]),"Missing")) -> 7208.15 | G14: =IF($A14="","",IF(OR(E14="Missing",F14="Missing"),"N/A",E14-F14)) -> 0 | H14: =IF($A14="","",IF(B14="Missing","Missing in App",IF(C14="Missing","Missing in Hotel Data",IF(D14=0,"Match","Discrepancy")))) -> Match | K14: ='System Generated 2026-08-24'!A14 -> Atukulu
A15: Atukulu | B15: =IF($A15="","",IFERROR(_xlfn.XLOOKUP($A15,'System Generated 2026-08-24'!$A:$A,'System Generated 2026-08-24'!$B:$B),"Missing")) -> 19.459 | C15: =IF($A15="","",IFERROR(_xlfn.XLOOKUP($A15,Table1[Item],Table1[Current Stock]),"Missing")) -> 19.459 | D15: =IF($A15="","",IF(OR(B15="Missing",C15="Missing"),"N/A",B15-C15)) -> 0 | E15: =IF($A15="","",IFERROR(_xlfn.XLOOKUP($A15,'System Generated 2026-08-24'!$A:$A,'System Generated 2026-08-24'!$E:$E),"Missing")) -> 963.22 | F15: =IF($A15="","",IFERROR(_xlfn.XLOOKUP($A15,Table1[Item],Table1[Total (₹)]),"Missing")) -> 963.221 | G15: =IF($A15="","",IF(OR(E15="Missing",F15="Missing"),"N/A",E15-F15)) -> -0.001 | H15: =IF($A15="","",IF(B15="Missing","Missing in App",IF(C15="Missing","Missing in Hotel Data",IF(D15=0,"Match","Discrepancy")))) -> Match | K15: ='System Generated 2026-08-24'!A15 -> Baby Corn
A16: Baby Corn | B16: =IF($A16="","",IFERROR(_xlfn.XLOOKUP($A16,'System Generated 2026-08-24'!$A:$A,'System Generated 2026-08-24'!$B:$B),"Missing")) -> 5 | C16: =IF($A16="","",IFERROR(_xlfn.XLOOKUP($A16,Table1[Item],Table1[Current Stock]),"Missing")) -> 5 | D16: =IF($A16="","",IF(OR(B16="Missing",C16="Missing"),"N/A",B16-C16)) -> 0 | E16: =IF($A16="","",IFERROR(_xlfn.XLOOKUP($A16,'System Generated 2026-08-24'!$A:$A,'System Generated 2026-08-24'!$E:$E),"Missing")) -> 600 | F16: =IF($A16="","",IFERROR(_xlfn.XLOOKUP($A16,Table1[Item],Table1[Total (₹)]),"Missing")) -> 600 | G16: =IF($A16="","",IF(OR(E16="Missing",F16="Missing"),"N/A",E16-F16)) -> 0 | H16: =IF($A16="","",IF(B16="Missing","Missing in App",IF(C16="Missing","Missing in Hotel Data",IF(D16=0,"Match","Discrepancy")))) -> Match | K16: ='System Generated 2026-08-24'!A16 -> Badam
A17: Badam | B17: =IF($A17="","",IFERROR(_xlfn.XLOOKUP($A17,'System Generated 2026-08-24'!$A:$A,'System Generated 2026-08-24'!$B:$B),"Missing")) -> 2.18 | C17: =IF($A17="","",IFERROR(_xlfn.XLOOKUP($A17,Table1[Item],Table1[Current Stock]),"Missing")) -> 2.18 | D17: =IF($A17="","",IF(OR(B17="Missing",C17="Missing"),"N/A",B17-C17)) -> 0 | E17: =IF($A17="","",IFERROR(_xlfn.XLOOKUP($A17,'System Generated 2026-08-24'!$A:$A,'System Generated 2026-08-24'!$E:$E),"Missing")) -> 2147.3 | F17: =IF($A17="","",IFERROR(_xlfn.XLOOKUP($A17,Table1[Item],Table1[Total (₹)]),"Missing")) -> 2147.3 | G17: =IF($A17="","",IF(OR(E17="Missing",F17="Missing"),"N/A",E17-F17)) -> 0 | H17: =IF($A17="","",IF(B17="Missing","Missing in App",IF(C17="Missing","Missing in Hotel Data",IF(D17=0,"Match","Discrepancy")))) -> Match | K17: ='System Generated 2026-08-24'!A17 -> Baking Powder
A18: Baking Powder | B18: =IF($A18="","",IFERROR(_xlfn.XLOOKUP($A18,'System Generated 2026-08-24'!$A:$A,'System Generated 2026-08-24'!$B:$B),"Missing")) -> 11 | C18: =IF($A18="","",IFERROR(_xlfn.XLOOKUP($A18,Table1[Item],Table1[Current Stock]),"Missing")) -> 11 | D18: =IF($A18="","",IF(OR(B18="Missing",C18="Missing"),"N/A",B18-C18)) -> 0 | E18: =IF($A18="","",IFERROR(_xlfn.XLOOKUP($A18,'System Generated 2026-08-24'!$A:$A,'System Generated 2026-08-24'!$E:$E),"Missing")) -> 396.86 | F18: =IF($A18="","",IFERROR(_xlfn.XLOOKUP($A18,Table1[Item],Table1[Total (₹)]),"Missing")) -> 396.86 | G18: =IF($A18="","",IF(OR(E18="Missing",F18="Missing"),"N/A",E18-F18)) -> 0 | H18: =IF($A18="","",IF(B18="Missing","Missing in App",IF(C18="Missing","Missing in Hotel Data",IF(D18=0,"Match","Discrepancy")))) -> Match | K18: ='System Generated 2026-08-24'!A18 -> Banana
... A394: Silver Pouch 9*12 | B394: =IF($A394="","",IFERROR(_xlfn.XLOOKUP($A394,'System Generated 2026-08-24'!$A:$A,'System Generated 2026-08-24'!$B:$B),"Missing")) -> 12 | C394: =IF($A394="","",IFERROR(_xlfn.XLOOKUP($A394,Table1[Item],Table1[Current Stock]),"Missing")) -> 12 | D394: =IF($A394="","",IF(OR(B394="Missing",C394="Missing"),"N/A",B394-C394)) -> 0 | E394: =IF($A394="","",IFERROR(_xlfn.XLOOKUP($A394,'System Generated 2026-08-24'!$A:$A,'System Generated 2026-08-24'!$E:$E),"Missing")) -> 1440 | F394: =IF($A394="","",IFERROR(_xlfn.XLOOKUP($A394,Table1[Item],Table1[Total (₹)]),"Missing")) -> 1440 | G394: =IF($A394="","",IF(OR(E394="Missing",F394="Missing"),"N/A",E394-F394)) -> 0 | H394: =IF($A394="","",IF(B394="Missing","Missing in App",IF(C394="Missing","Missing in Hotel Data",IF(D394=0,"Match","Discrepancy")))) -> Match | K394: ='System Generated 2026-08-24'!A394 -> Wooden Spoons Small
A395: Small Biscuit Box | B395: =IF($A395="","",IFERROR(_xlfn.XLOOKUP($A395,'System Generated 2026-08-24'!$A:$A,'System Generated 2026-08-24'!$B:$B),"Missing")) -> Missing | C395: =IF($A395="","",IFERROR(_xlfn.XLOOKUP($A395,Table1[Item],Table1[Current Stock]),"Missing")) -> 6 | D395: =IF($A395="","",IF(OR(B395="Missing",C395="Missing"),"N/A",B395-C395)) -> N/A | E395: =IF($A395="","",IFERROR(_xlfn.XLOOKUP($A395,'System Generated 2026-08-24'!$A:$A,'System Generated 2026-08-24'!$E:$E),"Missing")) -> Missing | F395: =IF($A395="","",IFERROR(_xlfn.XLOOKUP($A395,Table1[Item],Table1[Total (₹)]),"Missing")) -> 69.903 | G395: =IF($A395="","",IF(OR(E395="Missing",F395="Missing"),"N/A",E395-F395)) -> N/A | H395: =IF($A395="","",IF(B395="Missing","Missing in App",IF(C395="Missing","Missing in Hotel Data",IF(D395=0,"Match","Discrepancy")))) -> Missing in App | K395: ='Kapila hotel 21-08-26'!A2 -> 5cp
A396: Small Onion | B396: =IF($A396="","",IFERROR(_xlfn.XLOOKUP($A396,'System Generated 2026-08-24'!$A:$A,'System Generated 2026-08-24'!$B:$B),"Missing")) -> 8 | C396: =IF($A396="","",IFERROR(_xlfn.XLOOKUP($A396,Table1[Item],Table1[Current Stock]),"Missing")) -> 8 | D396: =IF($A396="","",IF(OR(B396="Missing",C396="Missing"),"N/A",B396-C396)) -> 0 | E396: =IF($A396="","",IFERROR(_xlfn.XLOOKUP($A396,'System Generated 2026-08-24'!$A:$A,'System Generated 2026-08-24'!$E:$E),"Missing")) -> 315.03 | F396: =IF($A396="","",IFERROR(_xlfn.XLOOKUP($A396,Table1[Item],Table1[Total (₹)]),"Missing")) -> 315.027 | G396: =IF($A396="","",IF(OR(E396="Missing",F396="Missing"),"N/A",E396-F396)) -> 0.003 | H396: =IF($A396="","",IF(B396="Missing","Missing in App",IF(C396="Missing","Missing in Hotel Data",IF(D396=0,"Match","Discrepancy")))) -> Match | K396: ='Kapila hotel 21-08-26'!A3 -> 20-20
A397: Soap Oil | B397: =IF($A397="","",IFERROR(_xlfn.XLOOKUP($A397,'System Generated 2026-08-24'!$A:$A,'System Generated 2026-08-24'!$B:$B),"Missing")) -> 133.5 | C397: =IF($A397="","",IFERROR(_xlfn.XLOOKUP($A397,Table1[Item],Table1[Current Stock]),"Missing")) -> 133.5 | D397: =IF($A397="","",IF(OR(B397="Missing",C397="Missing"),"N/A",B397-C397)) -> 0 | E397: =IF($A397="","",IFERROR(_xlfn.XLOOKUP($A397,'System Generated 2026-08-24'!$A:$A,'System Generated 2026-08-24'!$E:$E),"Missing")) -> 6007.5 | F397: =IF($A397="","",IFERROR(_xlfn.XLOOKUP($A397,Table1[Item],Table1[Total (₹)]),"Missing")) -> 6007.5 | G397: =IF($A397="","",IF(OR(E397="Missing",F397="Missing"),"N/A",E397-F397)) -> 0 | H397: =IF($A397="","",IF(B397="Missing","Missing in App",IF(C397="Missing","Missing in Hotel Data",IF(D397=0,"Match","Discrepancy")))) -> Match | K397: ='Kapila hotel 21-08-26'!A4 -> 3cp
A398: Soaps | B398: =IF($A398="","",IFERROR(_xlfn.XLOOKUP($A398,'System Generated 2026-08-24'!$A:$A,'System Generated 2026-08-24'!$B:$B),"Missing")) -> 1258 | C398: =IF($A398="","",IFERROR(_xlfn.XLOOKUP($A398,Table1[Item],Table1[Current Stock]),"Missing")) -> 1258 | D398: =IF($A398="","",IF(OR(B398="Missing",C398="Missing"),"N/A",B398-C398)) -> 0 | E398: =IF($A398="","",IFERROR(_xlfn.XLOOKUP($A398,'System Generated 2026-08-24'!$A:$A,'System Generated 2026-08-24'!$E:$E),"Missing")) -> 3249.83 | F398: =IF($A398="","",IFERROR(_xlfn.XLOOKUP($A398,Table1[Item],Table1[Total (₹)]),"Missing")) -> 3249.829 | G398: =IF($A398="","",IF(OR(E398="Missing",F398="Missing"),"N/A",E398-F398)) -> 0.001 | H398: =IF($A398="","",IF(B398="Missing","Missing in App",IF(C398="Missing","Missing in Hotel Data",IF(D398=0,"Match","Discrepancy")))) -> Match | K398: ='Kapila hotel 21-08-26'!A5 -> 8cp
A399: Soda 750 Ml | B399: =IF($A399="","",IFERROR(_xlfn.XLOOKUP($A399,'System Generated 2026-08-24'!$A:$A,'System Generated 2026-08-24'!$B:$B),"Missing")) -> 29 | C399: =IF($A399="","",IFERROR(_xlfn.XLOOKUP($A399,Table1[Item],Table1[Current Stock]),"Missing")) -> 29 | D399: =IF($A399="","",IF(OR(B399="Missing",C399="Missing"),"N/A",B399-C399)) -> 0 | E399: =IF($A399="","",IFERROR(_xlfn.XLOOKUP($A399,'System Generated 2026-08-24'!$A:$A,'System Generated 2026-08-24'!$E:$E),"Missing")) -> 524.74 | F399: =IF($A399="","",IFERROR(_xlfn.XLOOKUP($A399,Table1[Item],Table1[Total (₹)]),"Missing")) -> 524.738 | G399: =IF($A399="","",IF(OR(E399="Missing",F399="Missing"),"N/A",E399-F399)) -> 0.002 | H399: =IF($A399="","",IF(B399="Missing","Missing in App",IF(C399="Missing","Missing in Hotel Data",IF(D399=0,"Match","Discrepancy")))) -> Match | K399: ='Kapila hotel 21-08-26'!A6 -> Almond Syrup
A400: Softy Chocolate Cone Powder | B400: =IF($A400="","",IFERROR(_xlfn.XLOOKUP($A400,'System Generated 2026-08-24'!$A:$A,'System Generated 2026-08-24'!$B:$B),"Missing")) -> Missing | C400: =IF($A400="","",IFERROR(_xlfn.XLOOKUP($A400,Table1[Item],Table1[Current Stock]),"Missing")) -> 0 | D400: =IF($A400="","",IF(OR(B400="Missing",C400="Missing"),"N/A",B400-C400)) -> N/A | E400: =IF($A400="","",IFERROR(_xlfn.XLOOKUP($A400,'System Generated 2026-08-24'!$A:$A,'System Generated 2026-08-24'!$E:$E),"Missing")) -> Missing | F400: =IF($A400="","",IFERROR(_xlfn.XLOOKUP($A400,Table1[Item],Table1[Total (₹)]),"Missing")) -> 0 | G400: =IF($A400="","",IF(OR(E400="Missing",F400="Missing"),"N/A",E400-F400)) -> N/A | H400: =IF($A400="","",IF(B400="Missing","Missing in App",IF(C400="Missing","Missing in Hotel Data",IF(D400=0,"Match","Discrepancy")))) -> Missing in App | K400: ='Kapila hotel 21-08-26'!A7 -> Amchoor Powder
A401: Softy Chocolate Milk | B401: =IF($A401="","",IFERROR(_xlfn.XLOOKUP($A401,'System Generated 2026-08-24'!$A:$A,'System Generated 2026-08-24'!$B:$B),"Missing")) -> 6 | C401: =IF($A401="","",IFERROR(_xlfn.XLOOKUP($A401,Table1[Item],Table1[Current Stock]),"Missing")) -> 6 | D401: =IF($A401="","",IF(OR(B401="Missing",C401="Missing"),"N/A",B401-C401)) -> 0 | E401: =IF($A401="","",IFERROR(_xlfn.XLOOKUP($A401,'System Generated 2026-08-24'!$A:$A,'System Generated 2026-08-24'!$E:$E),"Missing")) -> 1071.94 | F401: =IF($A401="","",IFERROR(_xlfn.XLOOKUP($A401,Table1[Item],Table1[Total (₹)]),"Missing")) -> 1071.936 | G401: =IF($A401="","",IF(OR(E401="Missing",F401="Missing"),"N/A",E401-F401)) -> 0.004 | H401: =IF($A401="","",IF(B401="Missing","Missing in App",IF(C401="Missing","Missing in Hotel Data",IF(D401=0,"Match","Discrepancy")))) -> Match | K401: ='Kapila hotel 21-08-26'!A8 -> Amchur Raw
A402: Softy Vanilla Cone Powder | B402: =IF($A402="","",IFERROR(_xlfn.XLOOKUP($A402,'System Generated 2026-08-24'!$A:$A,'System Generated 2026-08-24'!$B:$B),"Missing")) -> Missing | C402: =IF($A402="","",IFERROR(_xlfn.XLOOKUP($A402,Table1[Item],Table1[Current Stock]),"Missing")) -> 0 | D402: =IF($A402="","",IF(OR(B402="Missing",C402="Missing"),"N/A",B402-C402)) -> N/A | E402: =IF($A402="","",IFERROR(_xlfn.XLOOKUP($A402,'System Generated 2026-08-24'!$A:$A,'System Generated 2026-08-24'!$E:$E),"Missing")) -> Missing | F402: =IF($A402="","",IFERROR(_xlfn.XLOOKUP($A402,Table1[Item],Table1[Total (₹)]),"Missing")) -> 0 | G402: =IF($A402="","",IF(OR(E402="Missing",F402="Missing"),"N/A",E402-F402)) -> N/A | H402: =IF($A402="","",IF(B402="Missing","Missing in App",IF(C402="Missing","Missing in Hotel Data",IF(D402=0,"Match","Discrepancy")))) -> Missing in App | K402: ='Kapila hotel 21-08-26'!A9 -> Anar
A403: Softy Vanilla Milk | B403: =IF($A403="","",IFERROR(_xlfn.XLOOKUP($A403,'System Generated 2026-08-24'!$A:$A,'System Generated 2026-08-24'!$B:$B),"Missing")) -> 18 | C403: =IF($A403="","",IFERROR(_xlfn.XLOOKUP($A403,Table1[Item],Table1[Current Stock]),"Missing")) -> 18 | D403: =IF($A403="","",IF(OR(B403="Missing",C403="Missing"),"N/A",B403-C403)) -> 0 | E403: =IF($A403="","",IFERROR(_xlfn.XLOOKUP($A403,'System Generated 2026-08-24'!$A:$A,'System Generated 2026-08-24'!$E:$E),"Missing")) -> 3017.81 | F403: =IF($A403="","",IFERROR(_xlfn.XLOOKUP($A403,Table1[Item],Table1[Total (₹)]),"Missing")) -> 3017.808 | G403: =IF($A403="","",IF(OR(E403="Missing",F403="Missing"),"N/A",E403-F403)) -> 0.002 | H403: =IF($A403="","",IF(B403="Missing","Missing in App",IF(C403="Missing","Missing in Hotel Data",IF(D403=0,"Match","Discrepancy")))) -> Match | K403: ='Kapila hotel 21-08-26'!A10 -> Anti Flies Floor Cleaner
A404: Somp | B404: =IF($A404="","",IFERROR(_xlfn.XLOOKUP($A404,'System Generated 2026-08-24'!$A:$A,'System Generated 2026-08-24'!$B:$B),"Missing")) -> 15.75 | C404: =IF($A404="","",IFERROR(_xlfn.XLOOKUP($A404,Table1[Item],Table1[Current Stock]),"Missing")) -> 15.75 | D404: =IF($A404="","",IF(OR(B404="Missing",C404="Missing"),"N/A",B404-C404)) -> 0 | E404: =IF($A404="","",IFERROR(_xlfn.XLOOKUP($A404,'System Generated 2026-08-24'!$A:$A,'System Generated 2026-08-24'!$E:$E),"Missing")) -> 3465 | F404: =IF($A404="","",IFERROR(_xlfn.XLOOKUP($A404,Table1[Item],Table1[Total (₹)]),"Missing")) -> 3465 | G404: =IF($A404="","",IF(OR(E404="Missing",F404="Missing"),"N/A",E404-F404)) -> 0 | H404: =IF($A404="","",IF(B404="Missing","Missing in App",IF(C404="Missing","Missing in Hotel Data",IF(D404=0,"Match","Discrepancy")))) -> Match | K404: ='Kapila hotel 21-08-26'!A11 -> Apples
A405: Somp White | B405: =IF($A405="","",IFERROR(_xlfn.XLOOKUP($A405,'System Generated 2026-08-24'!$A:$A,'System Generated 2026-08-24'!$B:$B),"Missing")) -> 19 | C405: =IF($A405="","",IFERROR(_xlfn.XLOOKUP($A405,Table1[Item],Table1[Current Stock]),"Missing")) -> 19 | D405: =IF($A405="","",IF(OR(B405="Missing",C405="Missing"),"N/A",B405-C405)) -> 0 | E405: =IF($A405="","",IFERROR(_xlfn.XLOOKUP($A405,'System Generated 2026-08-24'!$A:$A,'System Generated 2026-08-24'!$E:$E),"Missing")) -> 1799.14 | F405: =IF($A405="","",IFERROR(_xlfn.XLOOKUP($A405,Table1[Item],Table1[Total (₹)]),"Missing")) -> 1799.137 | G405: =IF($A405="","",IF(OR(E405="Missing",F405="Missing"),"N/A",E405-F405)) -> 0.003 | H405: =IF($A405="","",IF(B405="Missing","Missing in App",IF(C405="Missing","Missing in Hotel Data",IF(D405=0,"Match","Discrepancy")))) -> Match | K405: ='Kapila hotel 21-08-26'!A12 -> Aratikayalu
A406: Sora Kaya | B406: =IF($A406="","",IFERROR(_xlfn.XLOOKUP($A406,'System Generated 2026-08-24'!$A:$A,'System Generated 2026-08-24'!$B:$B),"Missing")) -> Missing | C406: =IF($A406="","",IFERROR(_xlfn.XLOOKUP($A406,Table1[Item],Table1[Current Stock]),"Missing")) -> 2.3 | D406: =IF($A406="","",IF(OR(B406="Missing",C406="Missing"),"N/A",B406-C406)) -> N/A | E406: =IF($A406="","",IFERROR(_xlfn.XLOOKUP($A406,'System Generated 2026-08-24'!$A:$A,'System Generated 2026-08-24'!$E:$E),"Missing")) -> Missing | F406: =IF($A406="","",IFERROR(_xlfn.XLOOKUP($A406,Table1[Item],Table1[Total (₹)]),"Missing")) -> 64.712 | G406: =IF($A406="","",IF(OR(E406="Missing",F406="Missing"),"N/A",E406-F406)) -> N/A | H406: =IF($A406="","",IF(B406="Missing","Missing in App",IF(C406="Missing","Missing in Hotel Data",IF(D406=0,"Match","Discrepancy")))) -> Missing in App | K406: ='Kapila hotel 21-08-26'!A13 -> Aromatic Powder
... A474: Wooden Spoons Small | B474: =IF($A474="","",IFERROR(_xlfn.XLOOKUP($A474,'System Generated 2026-08-24'!$A:$A,'System Generated 2026-08-24'!$B:$B),"Missing")) -> 36 | C474: =IF($A474="","",IFERROR(_xlfn.XLOOKUP($A474,Table1[Item],Table1[Current Stock]),"Missing")) -> 36 | D474: =IF($A474="","",IF(OR(B474="Missing",C474="Missing"),"N/A",B474-C474)) -> 0 | E474: =IF($A474="","",IFERROR(_xlfn.XLOOKUP($A474,'System Generated 2026-08-24'!$A:$A,'System Generated 2026-08-24'!$E:$E),"Missing")) -> 1440 | F474: =IF($A474="","",IFERROR(_xlfn.XLOOKUP($A474,Table1[Item],Table1[Total (₹)]),"Missing")) -> 1440 | G474: =IF($A474="","",IF(OR(E474="Missing",F474="Missing"),"N/A",E474-F474)) -> 0 | H474: =IF($A474="","",IF(B474="Missing","Missing in App",IF(C474="Missing","Missing in Hotel Data",IF(D474=0,"Match","Discrepancy")))) -> Match | K474: ='Kapila hotel 21-08-26'!A81 -> Chicken Big
B475: =IF($A475="","",IFERROR(_xlfn.XLOOKUP($A475,'System Generated 2026-08-24'!$A:$A,'System Generated 2026-08-24'!$B:$B),"Missing")) | C475: =IF($A475="","",IFERROR(_xlfn.XLOOKUP($A475,Table1[Item],Table1[Current Stock]),"Missing")) | D475: =IF($A475="","",IF(OR(B475="Missing",C475="Missing"),"N/A",B475-C475)) | E475: =IF($A475="","",IFERROR(_xlfn.XLOOKUP($A475,'System Generated 2026-08-24'!$A:$A,'System Generated 2026-08-24'!$E:$E),"Missing")) | F475: =IF($A475="","",IFERROR(_xlfn.XLOOKUP($A475,Table1[Item],Table1[Total (₹)]),"Missing")) | G475: =IF($A475="","",IF(OR(E475="Missing",F475="Missing"),"N/A",E475-F475)) | H475: =IF($A475="","",IF(B475="Missing","Missing in App",IF(C475="Missing","Missing in Hotel Data",IF(D475=0,"Match","Discrepancy")))) | K475: ='Kapila hotel 21-08-26'!A82 -> Chicken Biryani
B476: =IF($A476="","",IFERROR(_xlfn.XLOOKUP($A476,'System Generated 2026-08-24'!$A:$A,'System Generated 2026-08-24'!$B:$B),"Missing")) | C476: =IF($A476="","",IFERROR(_xlfn.XLOOKUP($A476,Table1[Item],Table1[Current Stock]),"Missing")) | D476: =IF($A476="","",IF(OR(B476="Missing",C476="Missing"),"N/A",B476-C476)) | E476: =IF($A476="","",IFERROR(_xlfn.XLOOKUP($A476,'System Generated 2026-08-24'!$A:$A,'System Generated 2026-08-24'!$E:$E),"Missing")) | F476: =IF($A476="","",IFERROR(_xlfn.XLOOKUP($A476,Table1[Item],Table1[Total (₹)]),"Missing")) | G476: =IF($A476="","",IF(OR(E476="Missing",F476="Missing"),"N/A",E476-F476)) | H476: =IF($A476="","",IF(B476="Missing","Missing in App",IF(C476="Missing","Missing in Hotel Data",IF(D476=0,"Match","Discrepancy")))) | K476: ='Kapila hotel 21-08-26'!A83 -> Chicken Small
B477: =IF($A477="","",IFERROR(_xlfn.XLOOKUP($A477,'System Generated 2026-08-24'!$A:$A,'System Generated 2026-08-24'!$B:$B),"Missing")) | C477: =IF($A477="","",IFERROR(_xlfn.XLOOKUP($A477,Table1[Item],Table1[Current Stock]),"Missing")) | D477: =IF($A477="","",IF(OR(B477="Missing",C477="Missing"),"N/A",B477-C477)) | E477: =IF($A477="","",IFERROR(_xlfn.XLOOKUP($A477,'System Generated 2026-08-24'!$A:$A,'System Generated 2026-08-24'!$E:$E),"Missing")) | F477: =IF($A477="","",IFERROR(_xlfn.XLOOKUP($A477,Table1[Item],Table1[Total (₹)]),"Missing")) | G477: =IF($A477="","",IF(OR(E477="Missing",F477="Missing"),"N/A",E477-F477)) | H477: =IF($A477="","",IF(B477="Missing","Missing in App",IF(C477="Missing","Missing in Hotel Data",IF(D477=0,"Match","Discrepancy")))) | K477: ='Kapila hotel 21-08-26'!A84 -> Chicken Staff
B478: =IF($A478="","",IFERROR(_xlfn.XLOOKUP($A478,'System Generated 2026-08-24'!$A:$A,'System Generated 2026-08-24'!$B:$B),"Missing")) | C478: =IF($A478="","",IFERROR(_xlfn.XLOOKUP($A478,Table1[Item],Table1[Current Stock]),"Missing")) | D478: =IF($A478="","",IF(OR(B478="Missing",C478="Missing"),"N/A",B478-C478)) | E478: =IF($A478="","",IFERROR(_xlfn.XLOOKUP($A478,'System Generated 2026-08-24'!$A:$A,'System Generated 2026-08-24'!$E:$E),"Missing")) | F478: =IF($A478="","",IFERROR(_xlfn.XLOOKUP($A478,Table1[Item],Table1[Total (₹)]),"Missing")) | G478: =IF($A478="","",IF(OR(E478="Missing",F478="Missing"),"N/A",E478-F478)) | H478: =IF($A478="","",IF(B478="Missing","Missing in App",IF(C478="Missing","Missing in Hotel Data",IF(D478=0,"Match","Discrepancy")))) | K478: ='Kapila hotel 21-08-26'!A85 -> Chilly Flakes Kg
B479: =IF($A479="","",IFERROR(_xlfn.XLOOKUP($A479,'System Generated 2026-08-24'!$A:$A,'System Generated 2026-08-24'!$B:$B),"Missing")) | C479: =IF($A479="","",IFERROR(_xlfn.XLOOKUP($A479,Table1[Item],Table1[Current Stock]),"Missing")) | D479: =IF($A479="","",IF(OR(B479="Missing",C479="Missing"),"N/A",B479-C479)) | E479: =IF($A479="","",IFERROR(_xlfn.XLOOKUP($A479,'System Generated 2026-08-24'!$A:$A,'System Generated 2026-08-24'!$E:$E),"Missing")) | F479: =IF($A479="","",IFERROR(_xlfn.XLOOKUP($A479,Table1[Item],Table1[Total (₹)]),"Missing")) | G479: =IF($A479="","",IF(OR(E479="Missing",F479="Missing"),"N/A",E479-F479)) | H479: =IF($A479="","",IF(B479="Missing","Missing in App",IF(C479="Missing","Missing in Hotel Data",IF(D479=0,"Match","Discrepancy")))) | K479: ='Kapila hotel 21-08-26'!A86 -> Chilly Flakes Sachets
B480: =IF($A480="","",IFERROR(_xlfn.XLOOKUP($A480,'System Generated 2026-08-24'!$A:$A,'System Generated 2026-08-24'!$B:$B),"Missing")) | C480: =IF($A480="","",IFERROR(_xlfn.XLOOKUP($A480,Table1[Item],Table1[Current Stock]),"Missing")) | D480: =IF($A480="","",IF(OR(B480="Missing",C480="Missing"),"N/A",B480-C480)) | E480: =IF($A480="","",IFERROR(_xlfn.XLOOKUP($A480,'System Generated 2026-08-24'!$A:$A,'System Generated 2026-08-24'!$E:$E),"Missing")) | F480: =IF($A480="","",IFERROR(_xlfn.XLOOKUP($A480,Table1[Item],Table1[Total (₹)]),"Missing")) | G480: =IF($A480="","",IF(OR(E480="Missing",F480="Missing"),"N/A",E480-F480)) | H480: =IF($A480="","",IF(B480="Missing","Missing in App",IF(C480="Missing","Missing in Hotel Data",IF(D480=0,"Match","Discrepancy")))) | K480: ='Kapila hotel 21-08-26'!A87 -> Chilly Powder
K481: ='Kapila hotel 21-08-26'!A88 -> Chinese Container 1000ml
K482: ='Kapila hotel 21-08-26'!A89 -> Chinese Container 500ml
...
